<?xml version="1.0" encoding="utf-8"?>
<mujoco>
    <compiler angle="radian" inertiafromgeom="auto" inertiagrouprange="4 5"/>
    <asset>

        <material name="cm_col" rgba="0.3 0.3 1.0 0.5" shininess="0" specular="0"/>
        <material name="cmred" rgba="0.38 0.19 0.2 1" shininess="1" reflectance=".7" specular=".5"/>
        <material name="cmwhite" rgba=".85 .85 .85 1" shininess="1" reflectance=".7" specular=".5"/>
        <material name="cmgrey" rgba=".65 .65 .65 1" shininess="1" reflectance="1" specular=".5"/>

        <material name="cmblack" rgba=".2 .2 .2 1" shininess="1" reflectance=".7" specular=".5"/>

        <mesh file="../objects/meshes/coffeemachine/body1.stl" name="body1"/>
        <mesh file="../objects/meshes/coffeemachine/body2.stl" name="body2"/>
        <mesh file="../objects/meshes/coffeemachine/button.stl" name="button"/>
        <mesh file="../objects/meshes/coffeemachine/mug.stl" name="mug"/>
        <mesh file="../objects/meshes/coffeemachine/handle.stl" name="handle"/>
        <mesh file="../objects/meshes/coffeemachine/spout.stl" name="spout"/>
        <mesh file="../objects/meshes/coffeemachine/spoutconnect.stl" name="spoutconnect"/>
        <mesh file="../objects/meshes/coffeemachine/buttonring.stl" name="buttonring"/>
        <mesh file="../objects/meshes/coffeemachine/bodypiece1.stl" name="bodypiece1"/>

    </asset>
    <default>

      <default class="cm_base">
          <joint armature="0.001" damping="2" limited="true"/>
          <geom conaffinity="0" contype="0" group="1" type="mesh"/>
          <position ctrllimited="true" ctrlrange="0 1.57"/>
          <default class="cm_viz">
              <geom condim="4" type="mesh"/>
          </default>
          <default class="cm_col">
              <geom conaffinity="1" condim="3" contype="1" group="4" material="cm_col" solimp="0.99 0.99 0.01" solref="0.01 1"/>
          </default>
      </default>
    </default>

    <worldbody>
        <body name="coffee_machine" pos="0 0 0">
            <body childclass="cm_base" name="coffeemachine">
                <body name="cm_link">
                    <geom name="1" material="cmred" mesh="body1" pos="0 0 0.115"/>
                    <geom name="2" material="cmred" mesh="body2" pos="0 -0.042 0.3"/>
                    <geom name="3" material="cmblack" mesh="spout" pos="0 -0.141 0.155"/>
                    <!-- <geom material="cmblack" euler="1.57 0 0" pos="0 -0.109 0.135" size="0.009 0.018" type="cylinder"/> -->
                    <geom name="4" material="cmblack" euler="1.57 0 0" pos="0 -0.109 0.135" size="0.009 .009 0.018" type="box"/>
                    <geom name="5" material="cmblack" euler="1.571 -0.0 0.0" mesh="buttonring" pos="0.0 -0.183 0.3"/>
                    <geom name="6" material="cmblack" mesh="bodypiece1" pos="0.0 0.0 0.115" />

                    <geom class="cm_col" pos="0.069 -0.133 0.3" size="0.031 0.05 0.035" type="box" />
                    <geom class="cm_col" pos="-0.069 -0.133 0.3" size="0.031 0.05 0.035" type="box" />
                    <geom class="cm_col" pos="0.0 -0.133 0.352" size="0.1 0.05 0.018" type="box" />
                    <geom class="cm_col" pos="0.0 -0.133 0.248" size="0.1 0.05 0.018" type="box" />
                    <geom class="cm_col" pos="0 0 0.115" size="0.1 0.098 0.115" type="box"/>
                    <geom class="cm_col" euler="1.57 0 0" pos="0 -0.109 0.135" size="0.009 0.018" type="cylinder"/>
                    <geom class="cm_col" pos="0.0 -0.141 0.152" size="0.016 0.041" type="cylinder"/>
                    <geom class="cm_col" pos="0 0 0.3" size="0.1 0.098 0.07" type="box"/>
                    <!-- <site name="coffee_goal" pos="0 -.22 0" size="0.01" rgba="1 0 0 1"/> -->
                </body>

                <body name="cmbutton" pos="0 0 0">
                    <geom material="cmgrey" euler="1.57 0 0" pos="0 -0.19 0.3" size="0.02 0.02 0.032" type="box" group="1"/>
                    <geom class="cm_col" euler="1.57 0 0" pos="0 -0.19 0.3" size="0.02 0.02 0.032" type="box" mass=".1"/>

                    <joint type="slide" range="0 0.03" axis="0 1 0" name="goal_slidey" pos="0 0 0" damping="1.0"/>
                    <body name="buttonStart" pos="0.0 -0.22 0.3"></body>
                </body>
            </body>
        </body>
        <!-- <site name="mug_goal" pos="0 0.6 0.02" size="0.01" rgba="0 1 0 1"/> -->
    </worldbody>
</mujoco>
