<mujoco>
    <compiler angle="radian" inertiafromgeom="auto" inertiagrouprange="4 5"/>
    <asset>
        <texture name="T_dial" type="cube" file="../textures/metal1.png"/>

        <material name="dial_col" rgba="0.3 0.3 1.0 0.5" shininess="0" specular="0"/>
        <material name="dial_metal" texture="T_dial" rgba=".35 .35 .35 1" shininess="1" reflectance=".7" specular=".5"/>
        <material name="dial_red" rgba=".6 0 0 1" shininess="1" reflectance=".7" specular=".5"/>

        <mesh file="../objects/meshes/dial/dial.stl" name="dial"/>
        <mesh file="../objects/meshes/dial/dialhead.stl" name="dialhead"/>

    </asset>

    <default>
      <default class="dial_base">
          <joint armature="0.001" damping="1" limited="true"/>
          <geom conaffinity="0" contype="0" group="1" type="mesh"/>
          <position ctrllimited="true" ctrlrange="0 1.57"/>
          <default class="dial_viz">
              <geom condim="4" type="mesh"/>
          </default>
          <default class="dial_col">
              <geom conaffinity="1" condim="3" contype="0" group="4" material="dial_col" solimp="0.99 0.99 0.01" solref="0.01 1"/>
          </default>

      </default>
    </default>

    <worldbody>
        <body name="dial" pos="0 0 0">
            <body childclass="dial_base">
                <joint name="knob_Joint_1" axis="0 0 1" type="hinge" limited="true" range="-3.14 3.14"/>

                <geom material="dial_metal" mesh="dial" pos="0 0 0.018"/>
                <geom material="dial_metal" mesh="dialhead" pos="0 0 0.051"/>
                <geom material="dial_red" pos="0 -0.038 0.062" size="0.004 0.01 0.006" type="box"/>

                <geom class="dial_col" pos="0 0 0.018" size="0.05 0.018" type="cylinder"/>
                <geom class="dial_col" pos="0 0 0.051" size="0.015 0.046 0.015" type="box"/>
                <body name="dial_tip" pos="0 -0.05 0.035"></body>
            </body>
            <site name="dialStart" pos="0 -0.05 0.035" size="0.005" rgba="0 0 1 1"/>
        </body>

        <site name="goal" pos="0. 0.74 0.07" size="0.02"
              rgba=".8 0 0 1"/>

    </worldbody>
</mujoco>
