<mujoco model="doorlockB">
    <compiler angle="radian" inertiafromgeom="auto" inertiagrouprange="4 5"/>
    <asset>
        <texture name="T_dl_met" type="cube" file="../textures/metal1.png"/>
        <texture name="T_dl_met2" type="cube" file="../textures/metal2.png"/>

        <material name="dl_col" rgba="0.3 0.3 1.0 0.5" shininess="0" specular="0"/>
        <material name="dl_metal" rgba=".75 .75 .75 1" texture="T_dl_met" texuniform="true" shininess="1" reflectance="1" specular="1"/>
        <material name="dl_metal2" rgba=".3 .32 .35 1" texture="T_dl_met2" texuniform="true" shininess="1" reflectance="1" specular="1"/>

        <mesh file="../objects/meshes/doorlock/safe.stl" name="safe"/>
        <mesh file="../objects/meshes/doorlock/door.stl" name="door"/>
        <mesh file="../objects/meshes/doorlock/door_handle.stl" name="door_handle"/>
        <mesh file="../objects/meshes/doorlock/handle_base.stl" name="handle_base"/>
        <mesh file="../objects/meshes/doorlock/lock.stl" name="lock"/>
        <mesh file="../objects/meshes/doorlock/lock_base.stl" name="lock_base"/>
    </asset>

    <default>

      <default class="dl_base">
          <joint armature="0.001" damping="2" limited="true"/>
          <geom conaffinity="0" contype="0" group="1" type="mesh"/>
          <position ctrllimited="true" ctrlrange="0 1.57"/>
          <default class="dl_viz">
              <geom condim="4" type="mesh"/>
          </default>
          <default class="dl_col">
              <geom conaffinity="1" condim="3" contype="1" group="4" material="dl_col" solimp="0.99 0.99 0.01" solref="0.01 1"/>
          </default>
      </default>
    </default>

    <worldbody>
        <body name="door" pos="0 0 0">
            <body childclass="dl_base" name="doorlockB">
                <geom material="dl_metal2" mesh="safe"/>
                <geom class="dl_col" pos="-0.204 0 0" size="0.016 0.106 0.15" type="box"/>
                <geom class="dl_col" pos="0.204 0 0" size="0.016 0.106 0.15" type="box"/>
                <geom class="dl_col" pos="0 0 0.138" size="0.188 0.106 0.012" type="box"/>
                <geom class="dl_col" pos="0 0 -0.138" size="0.189 0.106 0.012" type="box"/>
                <geom class="dl_col" pos="0 0.094 0" size="0.188 0.012 0.126" type="box"/>
                <body name="door_link" pos="-0.185 -0.1 0">
                    <body name="handleEnd" pos="0.44 -.13 0.0" > </body> <!--a site indicating the end of the handle-->
                    
                    <joint name="doorjoint" type="hinge" axis="0 0 1" range="-2 0"/>
                    <geom material="dl_metal2" mesh="door" pos="0.185 0 0"/>
                    
                    <body pos="0.325 -0.062 0" name="handle">
                        <geom name="handle" material="dl_metal" euler="1.57 0 0" mesh="door_handle"/>
                    </body>

                    <geom name="geom1" material="dl_metal" mesh="handle_base" pos="0.325 -0.006 0"/>
                    <!-- unable to load in isaacgym so replace with box -->
                    <!-- <geom name="geom2" material="dl_metal" pos="0 0 .07" size="0.013 .045" type="cylinder"/>
                    <geom name="geom3" material="dl_metal" pos="0 0 -.07" size="0.013 .045" type="cylinder"/> -->
                    <geom material="dl_metal" pos="0 0 .07" size="0.013 0.013 .045" type="box"/>
                    <geom material="dl_metal" pos="0 0 -.07" size="0.013 0.013 .045" type="box"/>

                    <geom class="dl_col" euler="1.57 0 0" pos="0.325 -0.006 0" size="0.028 0.012" type="cylinder"/>
                    <geom class="dl_col" euler="1.57 0 0" pos="0.325 -0.065 0" size="0.013 0.047" type="cylinder"/>
                    <geom class="dl_col" euler="0 1.57 0" pos="0.381 -0.12 0" size="0.019 0.075" type="cylinder"/>
                    <geom class="dl_col" euler="0 1.57 0" pos="0.395 -0.12 0" size="0.023 0.054" type="cylinder"/>
                    <geom class="dl_col" pos="0.185 0.0 0.0" size="0.18 0.01 0.123" type="box" />
                </body>
            </body>
        </body>
    </worldbody>
</mujoco>
