<mujoco>
    <compiler angle="radian" inertiafromgeom="auto" inertiagrouprange="4 5"/>
    <asset>
        <texture name="T_hdlprsmetal0" type="cube" file="../textures/metal1.png"/>
        <texture name="T_hdlprsmetal1" type="cube" file="../textures/metal2.png"/>

        <material name="hdlprs_col" rgba="0.3 0.3 1.0 0.5" shininess="0" specular="0"/>
        <material name="hdlprs_red" rgba=".5 0 0 1" shininess="1" reflectance=".7" specular=".5"/>
        <material name="hdlprs_black" rgba=".15 .15 .15 1" shininess="1" reflectance=".7" specular=".5"/>
        <material name="hdlprs_metal0" rgba=".55 .55 .55 1" texture="T_hdlprsmetal0" shininess="1" reflectance=".7" specular=".5"/>
        <material name="hdlprs_metal1" rgba=".65 .65 .65 1" texture="T_hdlprsmetal1" shininess="1" reflectance=".7" specular=".5"/>

        <mesh file="../objects/meshes/handle_press/handle_press_base.stl" name="handle_press_base"/>
        <mesh file="../objects/meshes/handle_press/handle_press_col1.stl" name="handle_press_col1"/>
        <mesh file="../objects/meshes/handle_press/handle_press_col2.stl" name="handle_press_col2"/>
        <mesh file="../objects/meshes/handle_press/handle_press_col3.stl" name="handle_press_col3"/>
        <mesh file="../objects/meshes/handle_press/handle_press_grip.stl" name="handle_press_grip"/>
        <mesh file="../objects/meshes/handle_press/handle_press_lever.stl" name="handle_press_lever"/>
        <mesh file="../objects/meshes/handle_press/handle_press_trim.stl" name="handle_press_trim"/>
    </asset>

    <default>
      <default class="hdlprs_base">
          <joint armature="0.001" damping="2" limited="true"/>
          <geom conaffinity="0" contype="0" group="1" type="mesh"/>
          <default class="hdlprs_viz">
              <geom condim="4" type="mesh"/>
          </default>
          <default class="hdlprs_col">
              <geom conaffinity="1" condim="3" contype="0" group="4" material="hdlprs_col" solimp="0.99 0.99 0.01" solref="0.01 1"/>
          </default>

      </default>
    </default>

    <worldbody>
        <body name="root" pos="0 0 0">
            <body name="box">
                <body childclass="hdlprs_base" name="hdlprs">
                    <geom material="hdlprs_metal0" mesh="handle_press_base"/>
                    <geom material="hdlprs_black" euler="0 1.57 0" mesh="handle_press_trim"/>
                    <geom class="hdlprs_col" euler="0 1.57 0" mesh="handle_press_col1" pos="0.055 0 0" type="mesh" />
                    <geom class="hdlprs_col" euler="0 1.57 0" mesh="handle_press_col2" pos="-0.066 0 0" type="mesh" />
                    <geom class="hdlprs_col" euler="0 1.57 0" mesh="handle_press_col3" pos="-0.009 0 0" type="mesh" />
                    <geom class="hdlprs_col" pos="0 -0.082 0.014" size="0.035 0.028 0.014" type="box" />
                    <body name="handle_link" pos="0 -0.05 0.15">
                        <joint type="slide" axis="0 0 1" range="-.1 0" damping="30" limited="true"/>
                        <body name="handleStart" pos="0 -0.166 0.022"/>
                        <body name="handleRight" pos="0.05 -0.166 0.014" />
                        <body name="handleCenter" pos="0 -0.12 0.0"/>

                        <geom material="hdlprs_red" euler="0 1.57 0" mesh="handle_press_grip" pos="0 -0.166 0" />
                        <geom material="hdlprs_black" mesh="handle_press_lever" pos="0 -0.089 0" />
                        <geom class="hdlprs_col" pos="0 -0.081 0" size="0.032 0.075 0.011" type="box" mass=".001"/>
                        <geom class="hdlprs_col" euler="0 1.57 0" pos="0 -0.166 0" size="0.022 0.07" type="cylinder" mass=".001"/>
                    </body>
                </body>

                <body name="goalPress" pos="0 -0.216 0.075"/>
                <body name="goalPull" pos="0 -0.216 0.172"/>
            </body>
        </body>
    </worldbody>
</mujoco>
