<mujoco>
    <compiler angle="radian" inertiafromgeom="auto" inertiagrouprange="4 5"/>
    <asset>
        <texture name="T_lever_met" type="cube" file="../textures/metal1.png"/>

        <material name="lever_col" rgba="0.3 0.3 1.0 0.5" shininess="0" specular="0"/>
        <material name="lever_blue" rgba="0 0 .5 1" shininess="1" reflectance="1" specular="1"/>
        <material name="lever_metal0" rgba=".65 .65 .65 1" texture="T_lever_met" shininess="1" reflectance=".7" specular=".5"/>
        <material name="lever_metal1" rgba=".35 .35 .35 1" texture="T_lever_met" shininess="1" reflectance=".7" specular=".5"/>

        <mesh file="../objects/meshes/lever/lever_axis.stl" name="lever_axis"/>
        <mesh file="../objects/meshes/lever/lever_base.stl" name="lever_base"/>
        <mesh file="../objects/meshes/lever/lever_handle.stl" name="lever_handle"/>
        <mesh file="../objects/meshes/lever/lever_rod.stl" name="lever_rod"/>
        <mesh file="../objects/meshes/lever/lever_rodbase.stl" name="lever_rodbase"/>

    </asset>
    <default>

      <default class="lever_base">
          <joint armature="0.001" damping="2" limited="true"/>
          <geom conaffinity="0" contype="0" group="1" type="mesh"/>
          <position ctrllimited="true" ctrlrange="0 1.57"/>
          <default class="lever_viz">
              <geom condim="4" type="mesh"/>
          </default>
          <default class="lever_col">
              <geom conaffinity="1" condim="3" contype="1" group="4" material="lever_col" solimp="0.99 0.99 0.01" solref="0.01 1"/>
          </default>
      </default>
    </default>

    <worldbody>
        <body name="lever" pos="0 0 0">
            <body childclass="lever_base">
                <geom material="lever_metal0" euler="0 1.57 0" mesh="lever_base"/>
                <geom class="lever_col" pos="0 0 0.125" size="0.041 0.083 0.125" type="box"/>
                <geom class="lever_col" euler="0 1.57 0" pos="0 0 0.25" size="0.083 0.041" type="cylinder"/>
                <geom class="lever_col" pos="0 0 0.013" size="0.05 0.092 0.013" type="box"/>
                <body name="lever_link1" pos="0.12 0 0.25">
                    <joint type="hinge" axis="1 0 0" range="-1.57 0 " name="LeverAxis"/>
                    <geom material="lever_metal1" euler="0 1.57 0" mesh="lever_axis"/>
                    <geom material="lever_metal0" euler="0 1.57 0" mesh="lever_rodbase"/>
                    <geom material="lever_blue" mesh="lever_handle" pos="0 -0.2 0" name="objGeom"/>
                    <geom material="lever_metal1" euler="1.57 0 0" mesh="lever_rod" pos="0 -0.1 0"/>
                    <geom class="lever_col" euler="0 1.57 0" size="0.038 0.016" type="cylinder" mass=".001"/>
                    <geom class="lever_col" euler="1.57 0 0" pos="0 -0.091 0" size="0.012 0.1" type="cylinder" mass=".001"/>
                    <geom class="lever_col" pos="0 -0.2 0" size="0.03" type="sphere" mass=".001"/>
                    <geom class="lever_col" euler="0 1.57 0" pos="-.025 0 0" size="0.016 0.046" type="cylinder" mass=".001"/>
                    <body name="leverStart" pos="0 -0.2 0"></body>
                </body>
            </body>
        </body>
        
    </worldbody>
</mujoco>
