<mujoco>
    <compiler angle="radian" inertiafromgeom="auto" inertiagrouprange="4 5"/>
    <asset>
      <texture name="T_therm_met" type="cube" file="../textures/metal1.png"/>

      <material name="therm_col" rgba="0.3 0.3 1.0 0.5" shininess="0" specular="0"/>
      <material name="therm_red" rgba="0.19 0.38 0.2 1" shininess="1" reflectance=".7" specular=".5"/>
      <material name="therm_white" rgba=".75 .75 .75 1" shininess="1" reflectance=".7" specular=".5"/>
      <material name="therm_metal_green" texture="T_therm_met" rgba=".45 .56 .52 1" shininess="1" reflectance="1" specular=".5"/>
      <material name="therm_metal" texture="T_therm_met" rgba=".85 .85 .85 1" shininess="1" reflectance="1" specular=".5"/>

      <mesh file="../objects/meshes/thermos/therm_base.stl" name="therm_base"/>
      <mesh file="../objects/meshes/thermos/therm_body.stl" name="therm_body"/>
      <mesh file="../objects/meshes/thermos/therm_cap.stl" name="therm_cap"/>
      <mesh file="../objects/meshes/thermos/therm_handle.stl" name="therm_handle"/>
      <mesh file="../objects/meshes/thermos/therm_trim.stl" name="therm_trim"/>

    </asset>
    <default>
        <default class="therm_base">
            <joint armature="0.001" damping="2" limited="true"/>
            <geom conaffinity="0" contype="0" group="1" type="mesh"/>
            <position ctrllimited="true" ctrlrange="0 1.57"/>
            <default class="therm_viz">
                <geom condim="4" type="mesh"/>
            </default>
            <default class="therm_col">
                <geom conaffinity="1" condim="3" contype="1" group="4" material="therm_col" solimp="0.99 0.99 0.01" solref="0.01 1"/>
            </default>
        </default>
    </default>

    <worldbody>
      <body name="thermos" pos="0 0 0">
        <body childclass="therm_base">
            <joint type="slide" range="-0.25 0.25" axis="1 0 0" name="obj_slidex" damping="1" limited="true"/>
            <joint type="slide" range="-0.25 0.25" axis="0 1 0" name="obj_slidey" damping="1" limited="true"/>
            <geom material="therm_metal" mesh="therm_base" pos="0 0 0.02"/>
            <geom material="therm_metal_green" mesh="therm_body" pos="0 0 0.14"/>
            <geom material="therm_metal" mesh="therm_cap" pos="0 0 0.285"/>
            <geom material="therm_metal" mesh="therm_handle" pos="0 -0.135 0.132"/>
            <geom material="therm_metal" mesh="therm_trim" pos="0 0 0.285"/>
            <geom class="therm_col" mesh="therm_trim" pos="0 0 0.285"/>
            <geom class="therm_col" mesh="therm_cap" pos="0 0 0.285" type="mesh"/>
            <geom class="therm_col" pos="0 0 0.14" size="0.06 0.1" type="cylinder"/>
            <geom class="therm_col" pos="0 0 0.02" size="0.062 0.02" type="cylinder"/>
            <geom class="therm_col" pos="0 -0.135 0.132" size="0.01 0.005 0.068" type="box"/>
            <geom class="therm_col" pos="0 -0.09 0.195" size="0.01 0.04 0.005" type="box"/>
            <geom class="therm_col" pos="0 -0.09 0.069" size="0.01 0.04 0.005" type="box"/>
            <body name="insertion" pos="0 -0.09 .110"></body>
        </body>

      </body>
    </worldbody>
</mujoco>
